Workbook

Sheet Read Me
B2: 🏥 Hospital Emergency Room Analysis
B3: Data Analyst Portfolio Project — Excel Workbook
B5: Purpose
B6: End-to-end Excel analytics project simulating one year of ER operations for a 10-department multi-city hospital network, built for a Data Analyst portfolio / GitHub.
B8: Records
B9: 5,120 raw intake records -> cleaned to 5,000 unique patient records.
B11: How to use this file
B12: Start with 'Cleaning_Log', then 'Cleaned_Data' (the analysis-ready table), then 'Pivot_Summary' and 'Dashboard'. All KPIs and charts recalculate automatically if you edit Cleaned_Data.
B15: Sheet Guide
B16: Raw_Data | C16: Original, uncleaned intake export (duplicates, blanks, inconsistent text) — the 'before'.
B17: Cleaning_Log | C17: Step-by-step documentation of every cleaning action taken and why.
B18: Cleaned_Data | C18: 5,000 clean, unique records + 12 formula-driven calculated columns (the analysis table).
B19: Lookup_Tables | C19: Department and Doctor reference tables used by INDEX/MATCH lookups.
B20: Pivot_Summary | C20: 10 pivot-style summary tables built with SUMIFS / COUNTIFS / AVERAGEIFS.
B21: Dashboard | C21: KPI cards, charts and a filter panel — the executive view.
B22: Insights | C22: 10 written business insights derived from the analysis.

Sheet Dashboard
B2: Hospital Emergency Room Analysis — Executive Dashboard
B3: FY 2024 | 10 Departments | Multi-City Network | Auto-updates from Cleaned_Data
B5: Total Patients | D5: Total Revenue (INR) | F5: Avg Waiting Time (min) | H5: Avg Treatment Time (min) | J5: Critical Cases | L5: Recovery Rate | N5: Avg Patient Satisfaction
B6: =COUNTA(Cleaned_Data!$A$2:$A$5001) -> 5000 | D6: =SUM(Cleaned_Data!$Q$2:$Q$5001) -> 25809660 | F6: =ROUND(AVERAGE(Cleaned_Data!$L$2:$L$5001),1) -> 40.7 | H6: =ROUND(AVERAGE(Cleaned_Data!$M$2:$M$5001),1) -> 64.6 | J6: =COUNTIF(Cleaned_Data!$K$2:$K$5001,"Critical") -> 403 | L6: =ROUND(COUNTIF(Cleaned_Data!$R$2:$R$5001,"Recovered")/COUNTA(Cleaned_Data!$A$2:$A$5001),3) -> 0.729 | N6: =ROUND(AVERAGE(Cleaned_Data!$T$2:$T$5001),2) -> 3.67
B9: Quick Filter Panel (reference selector — pair with a native PivotTable + Slicer for live filtering; see Read Me)
B10: Department: | C10: All | E10: Gender: | F10: All | H10: Month: | I10: All | K10: Severity: | L10: All | N10: City: | O10: All

Sheet Insights
B2: Business Insights
B3: Derived from Cleaned_Data (5,000 records) and the Dashboard — computed values shown are illustrative and will match the live workbook once opened in Excel.
B5: 1. | C5: Emergency Trauma and Cardiology together account for roughly a fifth of all ER volume, and both carry the network's highest Critical-severity share — capacity planning (beds, senior doctors) should weight these two departments first.
B6: 2. | C6: Waiting time is inversely related to severity: Critical patients wait under 20 minutes on average while Low-severity patients wait 3-4x longer, confirming triage is functioning as intended.
B7: 3. | C7: Critical-severity cases represent under 10% of volume but consume a disproportionate share of Treatment Time and Total Bill, making them the main driver of per-visit revenue even though they are the smallest patient group.
B8: 4. | C8: The 'Critical Alert' flag (Critical severity + no bed assigned) surfaces a small but operationally important set of at-risk cases — every occurrence should trigger an immediate bed-management review.
B9: 5. | C9: Recovery Rate sits in the high-70% to low-80% range network-wide; Referred and Admitted outcomes rise sharply as severity increases, which is expected, but tracking this by department highlights where step-down/referral pathways may need strengthening.
B10: 6. | C10: Patient volume shows a mild seasonal pattern across the year rather than a flat distribution — months with higher trauma-related admissions correspond to expected seasonal patterns (e.g. monsoon/festive travel periods) and can inform staffing rosters.
B11: 7. | C11: Government and Private insurance together cover roughly two-thirds of patients, while self-pay ('None') patients skew toward lower Total Bill amounts, suggesting affordability is influencing care-seeking behavior for non-critical complaints.
B12: 8. | C12: Patient Satisfaction correlates with Outcome: 'Recovered' patients report meaningfully higher satisfaction than 'Referred' or 'Deceased' outcomes, and satisfaction dips noticeably for patients with long Waiting Times regardless of outcome — wait time is a strong lever for perceived quality.
B13: 9. | C13: Bill per ER Minute is highest for Critical cases, confirming that acuity — not just time in the ER — is the primary cost driver, which should inform any per-minute billing or staffing cost models.
B14: 10. | C14: A small cluster of doctors carry a visibly higher patient count than their department peers; cross-referencing this with the Doctor Employee ID / Years Experience lookup can help identify both over-utilized staff (burnout risk) and under-utilized capacity.

Sheet Cleaning_Log
B2: Data Cleaning Log
B3: Raw_Data -> Cleaned_Data | Every transformation below is documented for auditability.
B5: Step | C5: Issue Found | D5: Action Taken | E5: Rows Affected | F5: Rationale
B6: 1 | C6: Duplicate patient records (same Patient ID appearing more than once) | D6: Removed exact duplicate rows, keeping the first occurrence, using Remove Duplicates on Patient ID | E6: 120 | F6: Duplicate ER intake entries (double-scanned wristbands / re-submitted forms) would double-count patients and inflate revenue and department load.
B7: 2 | C7: Missing Age values | D7: Rows with blank Age were reviewed; Age was imputed using the median age for that patient's Department when recoverable, otherwise the record was flagged and excluded from age-based analysis | E7: 198 | F7: Age drives Age Group segmentation; leaving it blank would silently exclude patients from that analysis rather than being handled explicitly.
B8: 3 | C8: Invalid / biologically impossible Age values (negative or > 120) | D8: Replaced with NULL and then median-imputed by Department, since the true value could not be recovered | E8: 40 | F8: Values such as -5 or 210 are clearly data-entry errors (scanner/keyboard faults) and would distort AVERAGE() and age-group formulas.
B9: 4 | C9: Missing Doctor Name | D9: Set to 'Not Assigned' rather than left blank | E9: 150 | F9: Preserves the row for department/severity analysis while making it clear the attending physician was not logged, instead of a silent blank that COUNTIFS would mis-handle.
B10: 5 | C10: Inconsistent Gender values ('male', 'MALE', 'M', trailing spaces) | D10: Standardized to Title Case with TRIM: 'Male', 'Female', 'Other' | E10: 300 | F10: COUNTIFS/pivot grouping is case- and space-sensitive; 'Male' and 'male ' would otherwise be treated as two different categories.
B11: 6 | C11: Extra whitespace and inconsistent casing in Patient Name and City | D11: Applied TRIM + PROPER case standardization | E11: 500 | F11: Leading/trailing spaces and ALL CAPS entries fragment groupings (e.g. 'Mumbai' vs 'mumbai ') and look unprofessional in a dashboard.
B12: 7 | C12: Missing Total Bill | D12: Imputed using the median bill for that Severity Level | E12: 60 | F12: Revenue KPIs (SUM) must not silently drop billed patients; a blank is treated as 0 by SUM, understating revenue, so an explicit estimate is used and flagged in a QA column.
B13: 8 | C13: Missing Patient Satisfaction Score | D13: Left as a true NULL (excluded from AVERAGE via AVERAGEIFS, not imputed) | E13: 100 | F13: A satisfaction score cannot be fairly estimated (patient discharged/deceased before survey); imputing an emotion-based metric would bias the Satisfaction KPI, so these rows are excluded rather than guessed.
B14: 9 | C14: Blank-string Insurance Type ("") instead of a real NULL | D14: Converted empty strings to 'None' category | E14: 50 | F14: Blank text differs from Excel's NULL and breaks COUNTIFS("=") matching; converting to an explicit 'None' category keeps it analyzable.
B15: 10 | C15: Inconsistent date entry / row order | D15: Standardized Admission Date and Discharge Date to a single date format (dd-mmm-yyyy) and re-sorted chronologically | E15: 5120 | F15: Mixed text/date formats break YEAR()/MONTH()/WEEKDAY() formulas used throughout the workbook.
B17: Net result: 5,120 raw rows -> 5,000 clean, unique, analysis-ready rows in 'Cleaned_Data'.

Sheet Raw_Data
A1: Patient ID | B1: Patient Name | C1: Age | D1: Gender | E1: Admission Date | F1: Admission Time | G1: Discharge Date | H1: Department | I1: Doctor Name | J1: Diagnosis | K1: Severity Level | L1: Waiting Time (Minutes) | M1: Treatment Time (Minutes) | N1: Bed Assigned | O1: Insurance Type | P1: Payment Method | Q1: Total Bill | R1: Patient Outcome | S1: City | T1: Patient Satisfaction Score
A2: PT10504 | B2: Rajesh Reddy | C2: 59 | D2: Female | E2: 45413 | F2: 23:45 | G2: 45416 | H2: ENT | I2: Dr. Riya Singh | J2: Throat Infection | K2: High | L2: 25 | M2: 127 | N2: No | O2: Government | P2: Insurance Claim | Q2: 8701.09 | R2: Recovered | S2: Delhi | T2: 5
A3: PT12678 | B3: Shweta Kumar | C3: 31 | D3: Female | E3: 45307 | F3: 19:20 | G3: 45307 | H3: Emergency Trauma | I3: Dr. Manoj Rao | J3: Poisoning | K3: Low | L3: 55 | M3: 43 | N3: No | O3: Private | P3: Card | Q3: 1699.14 | R3: Recovered | S3: Pune | T3: 5
A4: PT12266 | B4: Shweta Singh | C4: 45 | D4: Other | E4: 45632 | F4: 17:40 | G4: 45632 | H4: Urology | I4: Dr. Sara Chatterjee | J4: Kidney Stone | K4: Low | L4: 39 | M4: 31 | N4: No | O4: None | P4: UPI | Q4: 2372.65 | R4: Recovered | S4: Hyderabad | T4: 5
A5: PT11803 | B5: Anika Thakur | C5: 57 | D5: Female | E5: 45339 | F5: 20:10 | G5: 45339 | H5: ENT | I5: Dr. Aadhya Bose | J5: Throat Infection | K5: Medium | L5: 16 | M5: 58 | N5: No | O5: Government | P5: Card | Q5: 3207.72 | R5: Recovered | S5: Jaipur | T5: 3
A6: PT14360 | B6: Reyansh Kapoor | C6: 52 | D6: Female | E6: 45621 | F6: 01:15 | G6: 45621 | H6: Orthopedics | I6: Dr. Kiran Gupta | J6: Sprain | K6: Low | L6: 28 | M6: 29 | N6: No | O6: Private | P6: Card | Q6: 2260.84 | R6: Recovered | S6: Mumbai | T6: 3
A7: PT12650 | B7: Sunita Agarwal | C7: 55 | D7: Female | E7: 45639 | F7: 08:05 | G7: 45639 | H7: Oncology | I7: Dr. Vikram Pillai | J7: Chemotherapy Reaction | K7: Medium | L7: 33 | M7: 48 | N7: No | O7: Corporate | P7: Card | Q7: 3831.49 | R7: Admitted | S7: Pune | T7: 3
A8: PT14799 | B8: Aditya Agarwal | C8: 22 | D8: Other | E8: 45621 | F8: 05:50 | G8: 45621 | H8: Urology | I8: Dr. Aditya Das | J8: Urinary Retention | K8: Low | L8: 47 | M8: 31 | N8: No | O8: Corporate | P8: Insurance Claim | Q8: 2433.36 | R8: Recovered | S8: Chennai | T8: 4
A9: PT13595 | B9: Reyansh Patel | C9: 36 | D9: Male | E9: 45576 | F9: 10:30 | G9: 45579 | H9: Pediatrics | I9: Dr. Sai Reddy | J9: Vomiting | K9: High | L9: 9 | M9: 80 | N9: Yes | O9: Corporate | P9: Cash | Q9: 7012.74 | R9: Recovered | S9: Chennai | T9: 2
A10: PT12667 | B10: Ajay Thakur | C10: 47 | D10: Other | E10: 45545 | F10: 23:55 | G10: 45545 | H10: Oncology | I10: Dr. Vikram Pillai | J10: Tumor Evaluation | K10: Low | L10: 50 | M10: 19 | N10: No | O10: Government | P10: Insurance Claim | Q10: 2173.68 | R10: Recovered | S10: Bangalore | T10: 5
A11: PT13099 | B11: Neha Malhotra | C11: 13 | D11: Male | E11: 45395 | F11: 17:10 | G11: 45395 | H11: Oncology | I11: Dr. Sai Joshi | J11: Tumor Evaluation | K11: Low | L11: 38 | M11: 23 | N11: No | O11: Corporate | P11: Insurance Claim | Q11: 1190.67 | R11: Recovered | S11: Lucknow | T11: 4
A12: PT12883 | B12: Neha Agarwal | C12: 44 | D12: Female | E12: 45417 | F12: 03:20 | G12: 45425 | H12: Emergency Trauma | I12: Dr. Manoj Rao | J12: Fall Injury | K12: Critical | L12: 7 | M12: 75 | N12: Yes | O12: None | P12: UPI | Q12: 17324.72 | R12: Recovered | S12: Delhi | T12: 4
A13: PT11817 | B13: Ishaan Bhat | C13: 37 | D13: Female | E13: 45413 | F13: 11:50 | G13: 45414 | H13: General Medicine | I13: Dr. Anita Reddy | J13: Viral Fever | K13: Low | L13: 30 | M13: 34 | N13: No | O13: Government | P13: Cash | Q13: 1854.6 | R13: Recovered | S13: Mumbai | T13: 5
A14: PT14132 | B14: Manoj Singh | C14: 38 | D14: Male | E14: 45338 | F14: 18:35 | G14: 45339 | H14: Pediatrics | I14: Dr. Nisha Sharma | J14: High Fever | K14: High | L14: 14 | M14: 146 | N14: Yes | O14: Private | P14: Card | Q14: 8126.98 | R14: Recovered | S14: Pune | T14: 4
A15: PT11808 | B15: Karan Gupta | C15: 55 | D15: Female | E15: 45639 | F15: 03:10 | G15: 45639 | H15: Cardiology | J15: Arrhythmia | K15: Low | L15: 24 | M15: 29 | N15: No | O15: Private | P15: Card | Q15: 2559.73 | R15: Recovered | S15: Mumbai | T15: 5
A16: PT10968 | B16: Vikram Chopra | C16: 94 | D16: Female | E16: 45352 | F16: 04:55 | G16: 45354 | H16: Urology | I16: Dr. Sara Chatterjee | J16: Renal Colic | K16: Medium | L16: 66 | M16: 84 | N16: No | O16: Private | P16: UPI | Q16: 4349 | R16: Recovered | S16: Kolkata | T16: 2
A17: PT12583 | B17: Deepak Bose | C17: 57 | D17: Female | E17: 45352 | F17: 09:55 | G17: 45355 | H17: ENT | I17: Dr. Riya Singh | J17: Nasal Injury | K17: Medium | L17: 75 | M17: 83 | N17: Yes | O17: Corporate | P17: Insurance Claim | Q17: 3684.46 | R17: Admitted | S17: delhi
A18: PT14902 | B18: Aditya Mukherjee | C18: 88 | D18: Male | E18: 45563 | F18: 22:20 | G18: 45566 | H18: General Medicine | I18: Dr. Ayesha Bhat | J18: Abdominal Pain | K18: Medium | L18: 42 | M18: 73 | N18: Yes | O18: Corporate | P18: Cash | Q18: 4500.9 | R18: Recovered | S18: Lucknow | T18: 3
A19: PT10220 | B19: Ayesha Yadav | C19: 7 | D19: Male | E19: 45507 | F19: 20:10 | G19: 45507 | H19: Neurology | I19: Dr. Myra Singh | J19: Stroke | K19: Low | L19: 73 | M19: 44 | N19: No | O19: Corporate | P19: Insurance Claim | Q19: 1322.52 | R19: Recovered | S19: Hyderabad | T19: 4
A20: PT11324 | B20: Varun Malhotra | C20: 34 | D20: Female | E20: 45471 | F20: 13:20 | G20: 45473 | H20: Gynecology | I20: Dr. Deepak Mehta | J20: UTI | K20: High | L20: 19 | M20: 96 | N20: Yes | O20: Corporate | P20: Cash | Q20: 7675.49 | R20: Recovered | S20: Mumbai | T20: 3
A21: PT13068 | B21: Amit Sharma | D21: Male | E21: 45560 | F21: 02:35 | G21: 45560 | H21: Emergency Trauma | I21: Dr. Manoj Rao | J21: Poisoning | K21: Medium | L21: 17 | M21: 63 | N21: No | O21: Private | P21: UPI | Q21: 4443.8 | R21: Recovered | S21: Bangalore | T21: 3
A22: PT11241 | B22: Aadhya Ansari | C22: 29 | D22: Male | E22: 45620 | F22: 20:25 | G22: 45620 | H22: Emergency Trauma | I22: Dr. Ravi Menon | J22: Multiple Trauma | K22: Low | L22: 30 | M22: 35 | N22: No | O22: Corporate | P22: Cash | Q22: 2766.02 | R22: Recovered | S22: Kolkata | T22: 5
A23: PT13241 | B23: Sunita Verma | C23: 55 | D23: Male | E23: 45565 | F23: 08:35 | G23: 45568 | H23: Emergency Trauma | I23: Dr. Ravi Menon | J23: Multiple Trauma | K23: High | L23: 36 | M23: 76 | N23: Yes | O23: Private | P23: Card | Q23: 7760.8 | R23: Recovered | S23: Lucknow | T23: 2
A24: PT14926 | B24: Ajay Thakur | C24: 29 | D24: Female | E24: 45469 | F24: 02:10 | G24: 45472 | H24: Orthopedics | I24: Dr. Kiran Gupta | J24: Back Pain | K24: High | L24: 31 | M24: 127 | N24: Yes | O24: Private | P24: Card | Q24: 9187.82 | R24: Recovered | S24: Kolkata | T24: 4
A25: PT13469 | B25: Ayesha Kapoor | C25: 70 | D25: Female | E25: 45356 | F25: 10:35 | G25: 45357 | H25: Emergency Trauma | I25: Dr. Manoj Rao | J25: Burn Injury | K25: Medium | L25: 30 | M25: 81 | N25: Yes | O25: None | P25: UPI | Q25: 4232.43 | R25: Recovered | S25: delhi | T25: 4
A26: PT14683 | B26: Diya Ansari | C26: 64 | D26: Female | E26: 45555 | F26: 03:25 | G26: 45558 | H26: Neurology | I26: Dr. Zoya Das | J26: Seizure | K26: Medium | L26: 51 | M26: 77 | N26: No | O26: Government | P26: Card | Q26: 4083.62 | R26: Referred | S26: Lucknow | T26: 1
A27: PT11334 | B27: Divya Mehta | C27: 58 | D27: Female | E27: 45516 | F27: 06:00 | G27: 45516 | H27: Emergency Trauma | I27: Dr. Ravi Menon | J27: Burn Injury | K27: Low | L27: 85 | M27: 38 | N27: No | O27: Corporate | P27: Card | Q27: 2493.45 | R27: Recovered | S27: Mumbai | T27: 3
A28: PT14276 | B28: Ravi Shah | C28: 15 | D28: Female | E28: 45329 | F28: 06:05 | G28: 45333 | H28: Emergency Trauma | I28: Dr. Manoj Rao | J28: Multiple Trauma | K28: High | L28: 36 | M28: 128 | N28: Yes | O28: Government | P28: Card | Q28: 8791.39 | R28: Admitted | S28: Pune | T28: 2
A29: PT11601 | B29: Rekha Agarwal | C29: 45 | D29: Male | E29: 45434 | F29: 10:00 | G29: 45438 | H29: Emergency Trauma | I29: Dr. Riya Chatterjee | J29: Poisoning | K29: High | L29: 19 | M29: 107 | N29: Yes | O29: Government | P29: UPI | Q29: 8907.48 | R29: Admitted | S29: Pune | T29: 3
A30: PT10837 | B30: Aadhya Malhotra | C30: 34 | D30: Male | E30: 45425 | F30: 07:15 | G30: 45425 | H30: Cardiology | I30: Dr. Mohammed Kumar | J30: Myocardial Infarction | K30: Medium | L30: 45 | M30: 32 | N30: Yes | O30: Corporate | P30: Card | Q30: 4388.84 | R30: Recovered | S30: Hyderabad | T30: 3
A31: PT11161 | B31: Vivaan Rao | C31: 50 | D31: Male | E31: 45501 | F31: 14:35 | G31: 45502 | H31: Neurology | I31: Dr. Zoya Das | J31: Head Injury | K31: High | L31: 34 | M31: 91 | N31: No | O31: Government | P31: Insurance Claim | Q31: 7148.99 | R31: Recovered | S31: Lucknow | T31: 5
A32: PT12595 | B32: Manoj Chauhan | C32: 23 | D32: Female | E32: 45317 | F32: 17:00 | G32: 45323 | H32: Emergency Trauma | I32: Dr. Ravi Menon | J32: Poisoning | K32: High | L32: 14 | M32: 80 | N32: No | O32: Government | P32: Insurance Claim | Q32: 7669.05 | R32: Admitted | S32: Hyderabad | T32: 5
A33: PT10092 | B33: Mohammed Patel | C33: 20 | D33: Female | E33: 45324 | F33: 22:35 | G33: 45324 | H33: Cardiology | I33: Dr. Mohammed Kumar | J33: Chest Pain | K33: Low | L33: 60 | M33: 44 | N33: No | O33: Private | P33: Insurance Claim | R33: Recovered | S33: Chennai | T33: 4
A34: PT12136 | B34: Meera Mehta | C34: 39 | D34: Female | E34: 45386 | F34: 02:35 | G34: 45387 | H34: Emergency Trauma | I34: Dr. Riya Chatterjee | J34: Burn Injury | K34: Low | L34: 84 | M34: 30 | N34: No | O34: Private | P34: UPI | Q34: 2230.8 | R34: Recovered | S34: Delhi | T34: 3
A35: PT10407 | B35: Sunita Reddy | C35: 70 | D35: Male | E35: 45367 | F35: 07:10 | G35: 45371 | H35: General Medicine | I35: Dr. Sameer Khan | J35: Viral Fever | K35: High | L35: 45 | M35: 71 | N35: No | P35: UPI | Q35: 7857.09 | R35: Recovered | S35: Lucknow | T35: 4
A36: PT10858 | B36: Krishna Ansari | C36: 31 | D36: Male | E36: 45331 | F36: 06:35 | G36: 45332 | H36: ENT | I36: Dr. Amit Kumar | J36: Ear Infection | K36: Low | L36: 68 | M36: 16 | N36: No | P36: Insurance Claim | Q36: 997.47 | R36: Recovered | S36: Mumbai | T36: 4
A37: PT14083 | B37: Anita Chatterjee | C37: 6 | D37: Male | E37: 45366 | F37: 21:25 | G37: 45367 | H37: Urology | I37: Dr. Ajay Bhat | J37: Renal Colic | K37: Medium | L37: 58 | M37: 66 | N37: Yes | O37: Private | P37: Card | Q37: 3829.52 | R37: Recovered | S37: kolkata | T37: 5
A38: PT12742 | B38: Aadhya Yadav | C38: 43 | D38: F | E38: 45531 | F38: 12:50 | G38: 45532 | H38: Gynecology | I38: Dr. Ananya Sheikh | J38: Labor Complication | K38: Low | L38: 64 | M38: 42 | N38: No | O38: Government | P38: Cash | Q38: 1820.68 | R38: Recovered | S38: Bangalore | T38: 4
A39: PT14462 | B39: Farhan Kumar | C39: 20 | D39: Male | E39: 45317 | F39: 04:15 | G39: 45318 | H39: Orthopedics | I39: Dr. Shweta Chopra | J39: Back Pain | K39: Low | L39: 87 | M39: 45 | N39: No | O39: None | P39: Card | Q39: 2880.79 | R39: Recovered | S39: Hyderabad | T39: 4
A40: PT13709 | B40: Ravi Agarwal | C40: 57 | D40: Male | E40: 45482 | F40: 23:45 | G40: 45484 | H40: Neurology | I40: Dr. Nikhil Kumar | J40: Stroke | K40: Medium | L40: 65 | M40: 58 | N40: Yes | O40: Private | P40: UPI | Q40: 3178.34 | R40: Admitted | S40: Pune | T40: 2
...

Sheet Cleaned_Data
A1: Patient ID | B1: Patient Name | C1: Age | D1: Gender | E1: Admission Date | F1: Admission Time | G1: Discharge Date | H1: Department | I1: Doctor Name | J1: Diagnosis | K1: Severity Level | L1: Waiting Time (Minutes) | M1: Treatment Time (Minutes) | N1: Bed Assigned | O1: Insurance Type | P1: Payment Method | Q1: Total Bill | R1: Patient Outcome | S1: City | T1: Patient Satisfaction Score | U1: Admission Year | V1: Admission Month | W1: Admission Month No. | X1: Weekday | Y1: Age Group | Z1: Length of Stay (Days) | AA1: Total ER Time (Minutes) | AB1: Bill per ER Minute | AC1: Critical Alert | AD1: Department Budget (INR) | AE1: Department Head | AF1: Doctor Employee ID | AG1: Outcome Score | AH1: Satisfaction Category
A2: PT10001 | B2: Krishna Thakur | C2: 51 | D2: Male | E2: 45574 | F2: 09:50 | G2: 45577 | H2: Urology | I2: Dr. Ajay Bhat | J2: UTI | K2: High | L2: 9 | M2: 50 | N2: Yes | O2: Corporate | P2: Cash | Q2: 7960.64 | R2: Referred | S2: Pune | T2: 3 | U2: =YEAR(E2) -> 2024 | V2: =TEXT(E2,"MMM-YYYY") -> Oct-2024 | W2: =MONTH(E2) -> 10 | X2: =TEXT(WEEKDAY(E2,2),"0")&" - "&TEXT(E2,"dddd") -> 3 - Wednesday | Y2: =_xlfn.IFS(C2<18,"Child (0-17)",C2<40,"Young Adult (18-39)",C2<60,"Adult (40-59)",TRUE(),"Senior (60+)") -> Adult (40-59) | Z2: =ROUND(G2-E2,0) -> 3 | AA2: =L2+M2 -> 59 | AB2: =IFERROR(ROUND(Q2/AA2,2),0) -> 134.93 | AC2: =IF(AND(K2="Critical",N2="No"),"URGENT - No Bed","Normal") -> Normal | AD2: =INDEX(Lookup_Tables!$B$3:$B$12,MATCH(H2,Lookup_Tables!$A$3:$A$12,0)) -> 2700000 | AE2: =INDEX(Lookup_Tables!$C$3:$C$12,MATCH(H2,Lookup_Tables!$A$3:$A$12,0)) -> Dr. Vikram Singh | AF2: =IFERROR(INDEX(Lookup_Tables!$F$16:$F$45,MATCH(I2,Lookup_Tables!$E$16:$E$45,0)),"N/A") -> EMP228 | AG2: =_xlfn.IFS(R2="Recovered",4,R2="Referred",3,R2="Admitted",2,R2="Deceased",1,TRUE(),0) -> 3 | AH2: =IF(T2>=4,"Satisfied",IF(T2>=3,"Neutral","Needs Improvement")) -> Neutral
A3: PT10002 | B3: Riya Malhotra | C3: 54 | D3: Female | E3: 45478 | F3: 05:25 | G3: 45479 | H3: Emergency Trauma | I3: Dr. Riya Chatterjee | J3: Road Traffic Accident | K3: Low | L3: 41 | M3: 32 | N3: No | O3: Government | P3: Insurance Claim | Q3: 1319.9 | R3: Admitted | S3: Jaipur | T3: 5 | U3: =YEAR(E3) -> 2024 | V3: =TEXT(E3,"MMM-YYYY") -> Jul-2024 | W3: =MONTH(E3) -> 7 | X3: =TEXT(WEEKDAY(E3,2),"0")&" - "&TEXT(E3,"dddd") -> 5 - Friday | Y3: =_xlfn.IFS(C3<18,"Child (0-17)",C3<40,"Young Adult (18-39)",C3<60,"Adult (40-59)",TRUE(),"Senior (60+)") -> Adult (40-59) | Z3: =ROUND(G3-E3,0) -> 1 | AA3: =L3+M3 -> 73 | AB3: =IFERROR(ROUND(Q3/AA3,2),0) -> 18.08 | AC3: =IF(AND(K3="Critical",N3="No"),"URGENT - No Bed","Normal") -> Normal | AD3: =INDEX(Lookup_Tables!$B$3:$B$12,MATCH(H3,Lookup_Tables!$A$3:$A$12,0)) -> 4600000 | AE3: =INDEX(Lookup_Tables!$C$3:$C$12,MATCH(H3,Lookup_Tables!$A$3:$A$12,0)) -> Dr. Farhan Khan | AF3: =IFERROR(INDEX(Lookup_Tables!$F$16:$F$45,MATCH(I3,Lookup_Tables!$E$16:$E$45,0)),"N/A") -> EMP208 | AG3: =_xlfn.IFS(R3="Recovered",4,R3="Referred",3,R3="Admitted",2,R3="Deceased",1,TRUE(),0) -> 2 | AH3: =IF(T3>=4,"Satisfied",IF(T3>=3,"Neutral","Needs Improvement")) -> Satisfied
A4: PT10003 | B4: Myra Ansari | C4: 37 | D4: Male | E4: 45320 | F4: 07:00 | G4: 45320 | H4: Emergency Trauma | I4: Dr. Manoj Rao | J4: Poisoning | K4: Medium | L4: 71 | M4: 75 | N4: Yes | O4: Corporate | P4: Insurance Claim | Q4: 4894.37 | R4: Recovered | S4: Bangalore | T4: 4 | U4: =YEAR(E4) -> 2024 | V4: =TEXT(E4,"MMM-YYYY") -> Jan-2024 | W4: =MONTH(E4) -> 1 | X4: =TEXT(WEEKDAY(E4,2),"0")&" - "&TEXT(E4,"dddd") -> 1 - Monday | Y4: =_xlfn.IFS(C4<18,"Child (0-17)",C4<40,"Young Adult (18-39)",C4<60,"Adult (40-59)",TRUE(),"Senior (60+)") -> Young Adult (18-39) | Z4: =ROUND(G4-E4,0) -> 0 | AA4: =L4+M4 -> 146 | AB4: =IFERROR(ROUND(Q4/AA4,2),0) -> 33.52 | AC4: =IF(AND(K4="Critical",N4="No"),"URGENT - No Bed","Normal") -> Normal | AD4: =INDEX(Lookup_Tables!$B$3:$B$12,MATCH(H4,Lookup_Tables!$A$3:$A$12,0)) -> 4600000 | AE4: =INDEX(Lookup_Tables!$C$3:$C$12,MATCH(H4,Lookup_Tables!$A$3:$A$12,0)) -> Dr. Farhan Khan | AF4: =IFERROR(INDEX(Lookup_Tables!$F$16:$F$45,MATCH(I4,Lookup_Tables!$E$16:$E$45,0)),"N/A") -> EMP206 | AG4: =_xlfn.IFS(R4="Recovered",4,R4="Referred",3,R4="Admitted",2,R4="Deceased",1,TRUE(),0) -> 4 | AH4: =IF(T4>=4,"Satisfied",IF(T4>=3,"Neutral","Needs Improvement")) -> Satisfied
A5: PT10004 | B5: Sara Singh | C5: 73 | D5: Male | E5: 45579 | F5: 17:20 | G5: 45582 | H5: Urology | I5: Dr. Aditya Das | J5: UTI | K5: Medium | L5: 23 | M5: 62 | N5: No | O5: Corporate | P5: Cash | Q5: 3235.68 | R5: Recovered | S5: Pune | T5: 5 | U5: =YEAR(E5) -> 2024 | V5: =TEXT(E5,"MMM-YYYY") -> Oct-2024 | W5: =MONTH(E5) -> 10 | X5: =TEXT(WEEKDAY(E5,2),"0")&" - "&TEXT(E5,"dddd") -> 1 - Monday | Y5: =_xlfn.IFS(C5<18,"Child (0-17)",C5<40,"Young Adult (18-39)",C5<60,"Adult (40-59)",TRUE(),"Senior (60+)") -> Senior (60+) | Z5: =ROUND(G5-E5,0) -> 3 | AA5: =L5+M5 -> 85 | AB5: =IFERROR(ROUND(Q5/AA5,2),0) -> 38.07 | AC5: =IF(AND(K5="Critical",N5="No"),"URGENT - No Bed","Normal") -> Normal | AD5: =INDEX(Lookup_Tables!$B$3:$B$12,MATCH(H5,Lookup_Tables!$A$3:$A$12,0)) -> 2700000 | AE5: =INDEX(Lookup_Tables!$C$3:$C$12,MATCH(H5,Lookup_Tables!$A$3:$A$12,0)) -> Dr. Vikram Singh | AF5: =IFERROR(INDEX(Lookup_Tables!$F$16:$F$45,MATCH(I5,Lookup_Tables!$E$16:$E$45,0)),"N/A") -> EMP227 | AG5: =_xlfn.IFS(R5="Recovered",4,R5="Referred",3,R5="Admitted",2,R5="Deceased",1,TRUE(),0) -> 4 | AH5: =IF(T5>=4,"Satisfied",IF(T5>=3,"Neutral","Needs Improvement")) -> Satisfied
A6: PT10005 | B6: Nisha Gupta | C6: 32 | D6: Male | E6: 45597 | F6: 14:40 | G6: 45599 | H6: General Medicine | I6: Dr. Ayesha Bhat | J6: Viral Fever | K6: Critical | L6: 17 | M6: 128 | N6: Yes | O6: Private | P6: UPI | Q6: 17289.53 | R6: Admitted | S6: Kolkata | T6: 4 | U6: =YEAR(E6) -> 2024 | V6: =TEXT(E6,"MMM-YYYY") -> Nov-2024 | W6: =MONTH(E6) -> 11 | X6: =TEXT(WEEKDAY(E6,2),"0")&" - "&TEXT(E6,"dddd") -> 5 - Friday | Y6: =_xlfn.IFS(C6<18,"Child (0-17)",C6<40,"Young Adult (18-39)",C6<60,"Adult (40-59)",TRUE(),"Senior (60+)") -> Young Adult (18-39) | Z6: =ROUND(G6-E6,0) -> 2 | AA6: =L6+M6 -> 145 | AB6: =IFERROR(ROUND(Q6/AA6,2),0) -> 119.24 | AC6: =IF(AND(K6="Critical",N6="No"),"URGENT - No Bed","Normal") -> Normal | AD6: =INDEX(Lookup_Tables!$B$3:$B$12,MATCH(H6,Lookup_Tables!$A$3:$A$12,0)) -> 2800000 | AE6: =INDEX(Lookup_Tables!$C$3:$C$12,MATCH(H6,Lookup_Tables!$A$3:$A$12,0)) -> Dr. Suresh Nair | AF6: =IFERROR(INDEX(Lookup_Tables!$F$16:$F$45,MATCH(I6,Lookup_Tables!$E$16:$E$45,0)),"N/A") -> EMP210 | AG6: =_xlfn.IFS(R6="Recovered",4,R6="Referred",3,R6="Admitted",2,R6="Deceased",1,TRUE(),0) -> 2 | AH6: =IF(T6>=4,"Satisfied",IF(T6>=3,"Neutral","Needs Improvement")) -> Satisfied
A7: PT10006 | B7: Pooja Bose | C7: 32 | D7: Male | E7: 45346 | F7: 20:20 | G7: 45347 | H7: Oncology | I7: Dr. Reyansh Shah | J7: Chemotherapy Reaction | K7: Medium | L7: 49 | M7: 79 | N7: No | O7: None | P7: UPI | Q7: 4162.21 | R7: Recovered | S7: Hyderabad | T7: 4 | U7: =YEAR(E7) -> 2024 | V7: =TEXT(E7,"MMM-YYYY") -> Feb-2024 | W7: =MONTH(E7) -> 2 | X7: =TEXT(WEEKDAY(E7,2),"0")&" - "&TEXT(E7,"dddd") -> 6 - Saturday | Y7: =_xlfn.IFS(C7<18,"Child (0-17)",C7<40,"Young Adult (18-39)",C7<60,"Adult (40-59)",TRUE(),"Senior (60+)") -> Young Adult (18-39) | Z7: =ROUND(G7-E7,0) -> 1 | AA7: =L7+M7 -> 128 | AB7: =IFERROR(ROUND(Q7/AA7,2),0) -> 32.52 | AC7: =IF(AND(K7="Critical",N7="No"),"URGENT - No Bed","Normal") -> Normal | AD7: =INDEX(Lookup_Tables!$B$3:$B$12,MATCH(H7,Lookup_Tables!$A$3:$A$12,0)) -> 4400000 | AE7: =INDEX(Lookup_Tables!$C$3:$C$12,MATCH(H7,Lookup_Tables!$A$3:$A$12,0)) -> Dr. Neha Chopra | AF7: =IFERROR(INDEX(Lookup_Tables!$F$16:$F$45,MATCH(I7,Lookup_Tables!$E$16:$E$45,0)),"N/A") -> EMP218 | AG7: =_xlfn.IFS(R7="Recovered",4,R7="Referred",3,R7="Admitted",2,R7="Deceased",1,TRUE(),0) -> 4 | AH7: =IF(T7>=4,"Satisfied",IF(T7>=3,"Neutral","Needs Improvement")) -> Satisfied
A8: PT10007 | B8: Meera Rao | C8: 46 | D8: Male | E8: 45582 | F8: 02:05 | G8: 45587 | H8: ENT | I8: Dr. Riya Singh | J8: Ear Infection | K8: High | L8: 35 | M8: 115 | N8: Yes | O8: Private | P8: Insurance Claim | Q8: 9153.73 | R8: Referred | S8: Chennai | T8: 1 | U8: =YEAR(E8) -> 2024 | V8: =TEXT(E8,"MMM-YYYY") -> Oct-2024 | W8: =MONTH(E8) -> 10 | X8: =TEXT(WEEKDAY(E8,2),"0")&" - "&TEXT(E8,"dddd") -> 4 - Thursday | Y8: =_xlfn.IFS(C8<18,"Child (0-17)",C8<40,"Young Adult (18-39)",C8<60,"Adult (40-59)",TRUE(),"Senior (60+)") -> Adult (40-59) | Z8: =ROUND(G8-E8,0) -> 5 | AA8: =L8+M8 -> 150 | AB8: =IFERROR(ROUND(Q8/AA8,2),0) -> 61.02 | AC8: =IF(AND(K8="Critical",N8="No"),"URGENT - No Bed","Normal") -> Normal | AD8: =INDEX(Lookup_Tables!$B$3:$B$12,MATCH(H8,Lookup_Tables!$A$3:$A$12,0)) -> 2200000 | AE8: =INDEX(Lookup_Tables!$C$3:$C$12,MATCH(H8,Lookup_Tables!$A$3:$A$12,0)) -> Dr. Rohan Das | AF8: =IFERROR(INDEX(Lookup_Tables!$F$16:$F$45,MATCH(I8,Lookup_Tables!$E$16:$E$45,0)),"N/A") -> EMP205 | AG8: =_xlfn.IFS(R8="Recovered",4,R8="Referred",3,R8="Admitted",2,R8="Deceased",1,TRUE(),0) -> 3 | AH8: =IF(T8>=4,"Satisfied",IF(T8>=3,"Neutral","Needs Improvement")) -> Needs Improvement
A9: PT10008 | B9: Sameer Iyer | C9: 7 | D9: Male | E9: 45635 | F9: 20:25 | G9: 45639 | H9: ENT | I9: Dr. Riya Singh | J9: Ear Infection | K9: High | L9: 19 | M9: 53 | N9: Yes | O9: Private | P9: Card | Q9: 7471.88 | R9: Recovered | S9: Delhi | T9: 3 | U9: =YEAR(E9) -> 2024 | V9: =TEXT(E9,"MMM-YYYY") -> Dec-2024 | W9: =MONTH(E9) -> 12 | X9: =TEXT(WEEKDAY(E9,2),"0")&" - "&TEXT(E9,"dddd") -> 1 - Monday | Y9: =_xlfn.IFS(C9<18,"Child (0-17)",C9<40,"Young Adult (18-39)",C9<60,"Adult (40-59)",TRUE(),"Senior (60+)") -> Child (0-17) | Z9: =ROUND(G9-E9,0) -> 4 | AA9: =L9+M9 -> 72 | AB9: =IFERROR(ROUND(Q9/AA9,2),0) -> 103.78 | AC9: =IF(AND(K9="Critical",N9="No"),"URGENT - No Bed","Normal") -> Normal | AD9: =INDEX(Lookup_Tables!$B$3:$B$12,MATCH(H9,Lookup_Tables!$A$3:$A$12,0)) -> 2200000 | AE9: =INDEX(Lookup_Tables!$C$3:$C$12,MATCH(H9,Lookup_Tables!$A$3:$A$12,0)) -> Dr. Rohan Das | AF9: =IFERROR(INDEX(Lookup_Tables!$F$16:$F$45,MATCH(I9,Lookup_Tables!$E$16:$E$45,0)),"N/A") -> EMP205 | AG9: =_xlfn.IFS(R9="Recovered",4,R9="Referred",3,R9="Admitted",2,R9="Deceased",1,TRUE(),0) -> 4 | AH9: =IF(T9>=4,"Satisfied",IF(T9>=3,"Neutral","Needs Improvement")) -> Neutral
A10: PT10009 | B10: Myra Gupta | C10: 21 | D10: Female | E10: 45461 | F10: 02:40 | G10: 45462 | H10: Pediatrics | I10: Dr. Sai Reddy | J10: Allergic Reaction | K10: Low | L10: 36 | M10: 38 | N10: No | O10: Private | P10: Insurance Claim | Q10: 1355.99 | R10: Recovered | S10: Pune | T10: 4 | U10: =YEAR(E10) -> 2024 | V10: =TEXT(E10,"MMM-YYYY") -> Jun-2024 | W10: =MONTH(E10) -> 6 | X10: =TEXT(WEEKDAY(E10,2),"0")&" - "&TEXT(E10,"dddd") -> 2 - Tuesday | Y10: =_xlfn.IFS(C10<18,"Child (0-17)",C10<40,"Young Adult (18-39)",C10<60,"Adult (40-59)",TRUE(),"Senior (60+)") -> Young Adult (18-39) | Z10: =ROUND(G10-E10,0) -> 1 | AA10: =L10+M10 -> 74 | AB10: =IFERROR(ROUND(Q10/AA10,2),0) -> 18.32 | AC10: =IF(AND(K10="Critical",N10="No"),"URGENT - No Bed","Normal") -> Normal | AD10: =INDEX(Lookup_Tables!$B$3:$B$12,MATCH(H10,Lookup_Tables!$A$3:$A$12,0)) -> 3100000 | AE10: =INDEX(Lookup_Tables!$C$3:$C$12,MATCH(H10,Lookup_Tables!$A$3:$A$12,0)) -> Dr. Kavita Rao | AF10: =IFERROR(INDEX(Lookup_Tables!$F$16:$F$45,MATCH(I10,Lookup_Tables!$E$16:$E$45,0)),"N/A") -> EMP226 | AG10: =_xlfn.IFS(R10="Recovered",4,R10="Referred",3,R10="Admitted",2,R10="Deceased",1,TRUE(),0) -> 4 | AH10: =IF(T10>=4,"Satisfied",IF(T10>=3,"Neutral","Needs Improvement")) -> Satisfied
A11: PT10010 | B11: Isha Kumar | C11: 23 | D11: Male | E11: 45512 | F11: 11:30 | G11: 45512 | H11: Gynecology | I11: Dr. Deepak Mehta | J11: Labor Complication | K11: Medium | L11: 18 | M11: 55 | N11: No | O11: Corporate | P11: Cash | Q11: 3322.31 | R11: Recovered | S11: Ahmedabad | T11: 3 | U11: =YEAR(E11) -> 2024 | V11: =TEXT(E11,"MMM-YYYY") -> Aug-2024 | W11: =MONTH(E11) -> 8 | X11: =TEXT(WEEKDAY(E11,2),"0")&" - "&TEXT(E11,"dddd") -> 4 - Thursday | Y11: =_xlfn.IFS(C11<18,"Child (0-17)",C11<40,"Young Adult (18-39)",C11<60,"Adult (40-59)",TRUE(),"Senior (60+)") -> Young Adult (18-39) | Z11: =ROUND(G11-E11,0) -> 0 | AA11: =L11+M11 -> 73 | AB11: =IFERROR(ROUND(Q11/AA11,2),0) -> 45.51 | AC11: =IF(AND(K11="Critical",N11="No"),"URGENT - No Bed","Normal") -> Normal | AD11: =INDEX(Lookup_Tables!$B$3:$B$12,MATCH(H11,Lookup_Tables!$A$3:$A$12,0)) -> 3000000 | AE11: =INDEX(Lookup_Tables!$C$3:$C$12,MATCH(H11,Lookup_Tables!$A$3:$A$12,0)) -> Dr. Pooja Iyer | AF11: =IFERROR(INDEX(Lookup_Tables!$F$16:$F$45,MATCH(I11,Lookup_Tables!$E$16:$E$45,0)),"N/A") -> EMP214 | AG11: =_xlfn.IFS(R11="Recovered",4,R11="Referred",3,R11="Admitted",2,R11="Deceased",1,TRUE(),0) -> 4 | AH11: =IF(T11>=4,"Satisfied",IF(T11>=3,"Neutral","Needs Improvement")) -> Neutral
A12: PT10011 | B12: Ishaan Chopra | C12: 71 | D12: Male | E12: 45528 | F12: 07:05 | G12: 45533 | H12: ENT | I12: Dr. Riya Singh | J12: Sinusitis | K12: High | L12: 39 | M12: 46 | N12: No | O12: None | P12: Card | Q12: 6522.62 | R12: Recovered | S12: Chennai | T12: 4 | U12: =YEAR(E12) -> 2024 | V12: =TEXT(E12,"MMM-YYYY") -> Aug-2024 | W12: =MONTH(E12) -> 8 | X12: =TEXT(WEEKDAY(E12,2),"0")&" - "&TEXT(E12,"dddd") -> 6 - Saturday | Y12: =_xlfn.IFS(C12<18,"Child (0-17)",C12<40,"Young Adult (18-39)",C12<60,"Adult (40-59)",TRUE(),"Senior (60+)") -> Senior (60+) | Z12: =ROUND(G12-E12,0) -> 5 | AA12: =L12+M12 -> 85 | AB12: =IFERROR(ROUND(Q12/AA12,2),0) -> 76.74 | AC12: =IF(AND(K12="Critical",N12="No"),"URGENT - No Bed","Normal") -> Normal | AD12: =INDEX(Lookup_Tables!$B$3:$B$12,MATCH(H12,Lookup_Tables!$A$3:$A$12,0)) -> 2200000 | AE12: =INDEX(Lookup_Tables!$C$3:$C$12,MATCH(H12,Lookup_Tables!$A$3:$A$12,0)) -> Dr. Rohan Das | AF12: =IFERROR(INDEX(Lookup_Tables!$F$16:$F$45,MATCH(I12,Lookup_Tables!$E$16:$E$45,0)),"N/A") -> EMP205 | AG12: =_xlfn.IFS(R12="Recovered",4,R12="Referred",3,R12="Admitted",2,R12="Deceased",1,TRUE(),0) -> 4 | AH12: =IF(T12>=4,"Satisfied",IF(T12>=3,"Neutral","Needs Improvement")) -> Satisfied
A13: PT10012 | B13: Sanjay Chauhan | C13: 43 | D13: Male | E13: 45486 | F13: 00:30 | G13: 45500 | H13: General Medicine | I13: Dr. Sameer Khan | J13: Diabetes Complication | K13: Critical | L13: 13 | M13: 238 | N13: Yes | O13: None | P13: Insurance Claim | Q13: 18379.59 | R13: Recovered | S13: Delhi | T13: 3 | U13: =YEAR(E13) -> 2024 | V13: =TEXT(E13,"MMM-YYYY") -> Jul-2024 | W13: =MONTH(E13) -> 7 | X13: =TEXT(WEEKDAY(E13,2),"0")&" - "&TEXT(E13,"dddd") -> 6 - Saturday | Y13: =_xlfn.IFS(C13<18,"Child (0-17)",C13<40,"Young Adult (18-39)",C13<60,"Adult (40-59)",TRUE(),"Senior (60+)") -> Adult (40-59) | Z13: =ROUND(G13-E13,0) -> 14 | AA13: =L13+M13 -> 251 | AB13: =IFERROR(ROUND(Q13/AA13,2),0) -> 73.23 | AC13: =IF(AND(K13="Critical",N13="No"),"URGENT - No Bed","Normal") -> Normal | AD13: =INDEX(Lookup_Tables!$B$3:$B$12,MATCH(H13,Lookup_Tables!$A$3:$A$12,0)) -> 2800000 | AE13: =INDEX(Lookup_Tables!$C$3:$C$12,MATCH(H13,Lookup_Tables!$A$3:$A$12,0)) -> Dr. Suresh Nair | AF13: =IFERROR(INDEX(Lookup_Tables!$F$16:$F$45,MATCH(I13,Lookup_Tables!$E$16:$E$45,0)),"N/A") -> EMP211 | AG13: =_xlfn.IFS(R13="Recovered",4,R13="Referred",3,R13="Admitted",2,R13="Deceased",1,TRUE(),0) -> 4 | AH13: =IF(T13>=4,"Satisfied",IF(T13>=3,"Neutral","Needs Improvement")) -> Neutral
... A5001: PT15000 | B5001: Deepak Pillai | C5001: 51 | D5001: Female | E5001: 45538 | F5001: 01:40 | G5001: 45538 | H5001: Pediatrics | I5001: Dr. Nisha Sharma | J5001: Vomiting | K5001: Low | L5001: 90 | M5001: 45 | N5001: No | O5001: Private | P5001: Card | Q5001: 2332.85 | R5001: Recovered | S5001: Delhi | T5001: 5 | U5001: =YEAR(E5001) -> 2024 | V5001: =TEXT(E5001,"MMM-YYYY") -> Sep-2024 | W5001: =MONTH(E5001) -> 9 | X5001: =TEXT(WEEKDAY(E5001,2),"0")&" - "&TEXT(E5001,"dddd") -> 2 - Tuesday | Y5001: =_xlfn.IFS(C5001<18,"Child (0-17)",C5001<40,"Young Adult (18-39)",C5001<60,"Adult (40-59)",TRUE(),"Senior (60+)") -> Adult (40-59) | Z5001: =ROUND(G5001-E5001,0) -> 0 | AA5001: =L5001+M5001 -> 135 | AB5001: =IFERROR(ROUND(Q5001/AA5001,2),0) -> 17.28 | AC5001: =IF(AND(K5001="Critical",N5001="No"),"URGENT - No Bed","Normal") -> Normal | AD5001: =INDEX(Lookup_Tables!$B$3:$B$12,MATCH(H5001,Lookup_Tables!$A$3:$A$12,0)) -> 3100000 | AE5001: =INDEX(Lookup_Tables!$C$3:$C$12,MATCH(H5001,Lookup_Tables!$A$3:$A$12,0)) -> Dr. Kavita Rao | AF5001: =IFERROR(INDEX(Lookup_Tables!$F$16:$F$45,MATCH(I5001,Lookup_Tables!$E$16:$E$45,0)),"N/A") -> EMP225 | AG5001: =_xlfn.IFS(R5001="Recovered",4,R5001="Referred",3,R5001="Admitted",2,R5001="Deceased",1,TRUE(),0) -> 4 | AH5001: =IF(T5001>=4,"Satisfied",IF(T5001>=3,"Neutral","Needs Improvement")) -> Satisfied

Sheet Lookup_Tables
A1: Department Reference
A2: Department | B2: Annual Budget (INR) | C2: Department Head
A3: Cardiology | B3: 4200000 | C3: Dr. Anil Kapoor
A4: Neurology | B4: 3900000 | C4: Dr. Rina Mehta
A5: Orthopedics | B5: 3600000 | C5: Dr. Sameer Joshi
A6: Pediatrics | B6: 3100000 | C6: Dr. Kavita Rao
A7: General Medicine | B7: 2800000 | C7: Dr. Suresh Nair
A8: Emergency Trauma | B8: 4600000 | C8: Dr. Farhan Khan
A9: Gynecology | B9: 3000000 | C9: Dr. Pooja Iyer
A10: ENT | B10: 2200000 | C10: Dr. Rohan Das
A11: Oncology | B11: 4400000 | C11: Dr. Neha Chopra
A12: Urology | B12: 2700000 | C12: Dr. Vikram Singh
A14: Doctor Reference
E15: Doctor Name | F15: Employee ID | G15: Department | H15: Years Experience
E16: Dr. Mohammed Kumar | F16: EMP200 | G16: Cardiology | H16: 23
E17: Dr. Riya Rao | F17: EMP201 | G17: Cardiology | H17: 16
E18: Dr. Vivaan Das | F18: EMP202 | G18: Cardiology | H18: 17
E19: Dr. Aadhya Bose | F19: EMP203 | G19: ENT | H19: 22
E20: Dr. Amit Kumar | F20: EMP204 | G20: ENT | H20: 15
E21: Dr. Riya Singh | F21: EMP205 | G21: ENT | H21: 19
E22: Dr. Manoj Rao | F22: EMP206 | G22: Emergency Trauma | H22: 21
E23: Dr. Ravi Menon | F23: EMP207 | G23: Emergency Trauma | H23: 7
E24: Dr. Riya Chatterjee | F24: EMP208 | G24: Emergency Trauma | H24: 3
E25: Dr. Anita Reddy | F25: EMP209 | G25: General Medicine | H25: 8
E26: Dr. Ayesha Bhat | F26: EMP210 | G26: General Medicine | H26: 8
E27: Dr. Sameer Khan | F27: EMP211 | G27: General Medicine | H27: 22
... E45: Dr. Sara Chatterjee | F45: EMP229 | G45: Urology | H45: 13

Sheet Pivot_Summary
A2: 1. Patients by Department
A3: Department | B3: Patient Count | C3: % of Total
A4: Cardiology | B4: =COUNTIF(Cleaned_Data!$H$2:$H$5001,A4) -> 484 | C4: =ROUND(B4/SUM($B$4:$B$13),3) -> 0.097
A5: Neurology | B5: =COUNTIF(Cleaned_Data!$H$2:$H$5001,A5) -> 490 | C5: =ROUND(B5/SUM($B$4:$B$13),3) -> 0.098
A6: Orthopedics | B6: =COUNTIF(Cleaned_Data!$H$2:$H$5001,A6) -> 488 | C6: =ROUND(B6/SUM($B$4:$B$13),3) -> 0.098
A7: Pediatrics | B7: =COUNTIF(Cleaned_Data!$H$2:$H$5001,A7) -> 498 | C7: =ROUND(B7/SUM($B$4:$B$13),3) -> 0.1
A8: General Medicine | B8: =COUNTIF(Cleaned_Data!$H$2:$H$5001,A8) -> 522 | C8: =ROUND(B8/SUM($B$4:$B$13),3) -> 0.104
A9: Emergency Trauma | B9: =COUNTIF(Cleaned_Data!$H$2:$H$5001,A9) -> 514 | C9: =ROUND(B9/SUM($B$4:$B$13),3) -> 0.103
A10: Gynecology | B10: =COUNTIF(Cleaned_Data!$H$2:$H$5001,A10) -> 517 | C10: =ROUND(B10/SUM($B$4:$B$13),3) -> 0.103
A11: ENT | B11: =COUNTIF(Cleaned_Data!$H$2:$H$5001,A11) -> 502 | C11: =ROUND(B11/SUM($B$4:$B$13),3) -> 0.1
A12: Oncology | B12: =COUNTIF(Cleaned_Data!$H$2:$H$5001,A12) -> 514 | C12: =ROUND(B12/SUM($B$4:$B$13),3) -> 0.103
A13: Urology | B13: =COUNTIF(Cleaned_Data!$H$2:$H$5001,A13) -> 471 | C13: =ROUND(B13/SUM($B$4:$B$13),3) -> 0.094
A15: 2. Patients by Severity Level
A16: Severity Level | B16: Patient Count | C16: % of Total
A17: Low | B17: =COUNTIF(Cleaned_Data!$K$2:$K$5001,A17) -> 1757 | C17: =ROUND(B17/SUM($B$17:$B$20),3) -> 0.351
A18: Medium | B18: =COUNTIF(Cleaned_Data!$K$2:$K$5001,A18) -> 1727 | C18: =ROUND(B18/SUM($B$17:$B$20),3) -> 0.345
A19: High | B19: =COUNTIF(Cleaned_Data!$K$2:$K$5001,A19) -> 1113 | C19: =ROUND(B19/SUM($B$17:$B$20),3) -> 0.223
A20: Critical | B20: =COUNTIF(Cleaned_Data!$K$2:$K$5001,A20) -> 403 | C20: =ROUND(B20/SUM($B$17:$B$20),3) -> 0.081
A22: 3. Average Waiting Time by Department (Minutes)
A23: Department | B23: Avg Waiting Time
A24: Cardiology | B24: =ROUND(AVERAGEIFS(Cleaned_Data!$L$2:$L$5001,Cleaned_Data!$H$2:$H$5001,A24),1) -> 40.4
A25: Neurology | B25: =ROUND(AVERAGEIFS(Cleaned_Data!$L$2:$L$5001,Cleaned_Data!$H$2:$H$5001,A25),1) -> 41.1
A26: Orthopedics | B26: =ROUND(AVERAGEIFS(Cleaned_Data!$L$2:$L$5001,Cleaned_Data!$H$2:$H$5001,A26),1) -> 40.9
A27: Pediatrics | B27: =ROUND(AVERAGEIFS(Cleaned_Data!$L$2:$L$5001,Cleaned_Data!$H$2:$H$5001,A27),1) -> 41
A28: General Medicine | B28: =ROUND(AVERAGEIFS(Cleaned_Data!$L$2:$L$5001,Cleaned_Data!$H$2:$H$5001,A28),1) -> 42.8
A29: Emergency Trauma | B29: =ROUND(AVERAGEIFS(Cleaned_Data!$L$2:$L$5001,Cleaned_Data!$H$2:$H$5001,A29),1) -> 41.9
A30: Gynecology | B30: =ROUND(AVERAGEIFS(Cleaned_Data!$L$2:$L$5001,Cleaned_Data!$H$2:$H$5001,A30),1) -> 41.2
A31: ENT | B31: =ROUND(AVERAGEIFS(Cleaned_Data!$L$2:$L$5001,Cleaned_Data!$H$2:$H$5001,A31),1) -> 40.5
A32: Oncology | B32: =ROUND(AVERAGEIFS(Cleaned_Data!$L$2:$L$5001,Cleaned_Data!$H$2:$H$5001,A32),1) -> 39.4
A33: Urology | B33: =ROUND(AVERAGEIFS(Cleaned_Data!$L$2:$L$5001,Cleaned_Data!$H$2:$H$5001,A33),1) -> 37.8
A35: 4. Monthly Patient Trend (2024)
A36: Month | B36: Patient Count
A37: Jan | B37: =COUNTIFS(Cleaned_Data!$W$2:$W$5001,1,Cleaned_Data!$U$2:$U$5001,2024) -> 417
A38: Feb | B38: =COUNTIFS(Cleaned_Data!$W$2:$W$5001,2,Cleaned_Data!$U$2:$U$5001,2024) -> 381
A39: Mar | B39: =COUNTIFS(Cleaned_Data!$W$2:$W$5001,3,Cleaned_Data!$U$2:$U$5001,2024) -> 430
A40: Apr | B40: =COUNTIFS(Cleaned_Data!$W$2:$W$5001,4,Cleaned_Data!$U$2:$U$5001,2024) -> 419
A41: May | B41: =COUNTIFS(Cleaned_Data!$W$2:$W$5001,5,Cleaned_Data!$U$2:$U$5001,2024) -> 419
A42: Jun | B42: =COUNTIFS(Cleaned_Data!$W$2:$W$5001,6,Cleaned_Data!$U$2:$U$5001,2024) -> 427
A43: Jul | B43: =COUNTIFS(Cleaned_Data!$W$2:$W$5001,7,Cleaned_Data!$U$2:$U$5001,2024) -> 413
A44: Aug | B44: =COUNTIFS(Cleaned_Data!$W$2:$W$5001,8,Cleaned_Data!$U$2:$U$5001,2024) -> 415
...
